# Complete Diagnosis and Fix

## What I Found

Based on your error output, I can see:
1. ✅ Modal is working and showing project info
2. ✅ conversation_id is being passed (`ai_generated_code_from_coder_a_project_6f1d6f4a`)
3. ❌ Repository created (README + gitignore) but OTHER files not pushed
4. ❌ 404 error when pushing files
5. ❌ NO debug logs appearing (this is concerning!)

## Root Cause

The issue is that **the debug logs aren't appearing**, which means one of two things:
1. The code isn't reaching `upload_project_to_github` method
2. The logging isn't being output to console

BUT since we see `[ERROR] Manual upload failed`, we know the endpoint IS being called.

## The Real Problem

Looking at the modal output:
```
Location: generated\projects\ai_generated_code_from_coder_a_project_6f1d6f4a\src\calculate.py
```

This shows **ONLY ONE FILE PATH** instead of the **PROJECT DIRECTORY**.

The `last_project_saved` stores:
- `conversation_id`
- `project_name`
- `filepath` (single file)

But `upload_project_to_github` needs the `conversation_id` to find the project in `active_projects`.

## The Fix

The system SHOULD work because:
1. `save_code` adds the project to `active_projects` with the `conversation_id`
2. `upload_project_to_github` looks up the project using `conversation_id`
3. Project directory should have all files

But something is going wrong. Let me add MORE diagnostic logging to catch the issue.

## Next Step

I need to add logging at the VERY START of the upload endpoint to see what's being received.

